Workbook

Sheet Dashboard
A1: 📊 CORPORATE BUDGET PERFORMANCE DASHBOARD — FY 2024
A3: Techbridge Nigeria Ltd | Finance Department | Data as at: December 2024
A5: Total Budget (NGN) | D5: Total Actual Spend | G5: Budget Variance | J5: Approval Rate
A7: =SUM(Budget_vs_Actual!B5:B10) -> 163500000 | D7: =SUM(Budget_vs_Actual!G5:G10) -> 147196032 | G7: =SUM(Budget_vs_Actual!H5:H10) -> -16303968 | J7: =IFERROR(COUNTIF(Cleaned_Data!I2:I121,"Approved")/COUNTA(Cleaned_Data!I2:I121),0) -> 0
A10: BUDGET vs ACTUAL BY DEPARTMENT | G10: TOP SPEND CATEGORIES
A11: Department | B11: Budget (NGN) | C11: Actual (NGN) | D11: Variance | E11: Status | G11: Category | H11: Total Spend | I11: % of Budget
A12: Sales | B12: =Budget_vs_Actual!B5 -> 45000000 | C12: =Budget_vs_Actual!G5 -> 38869485 | D12: =Budget_vs_Actual!H5 -> -6130515 | E12: =Budget_vs_Actual!J5 -> ❌ Over Budget | G12: =IFERROR(INDEX(Category_Analysis!$A$4:$A$13,MATCH(LARGE(Category_Analysis!$B$4:$B$13,1),Category_Analysis!$B$4:$B$13,0)),"N/A") -> Training | H12: =IFERROR(LARGE(Category_Analysis!$B$4:$B$13,1),0) -> 48612970 | I12: =IFERROR(H12/SUM(Category_Analysis!$B$4:$B$13),0) -> 0.17135168
A13: Operations | B13: =Budget_vs_Actual!B6 -> 38000000 | C13: =Budget_vs_Actual!G6 -> 34049545 | D13: =Budget_vs_Actual!H6 -> -3950455 | E13: =Budget_vs_Actual!J6 -> ❌ Over Budget | G13: =IFERROR(INDEX(Category_Analysis!$A$4:$A$13,MATCH(LARGE(Category_Analysis!$B$4:$B$13,2),Category_Analysis!$B$4:$B$13,0)),"N/A") -> Equipment | H13: =IFERROR(LARGE(Category_Analysis!$B$4:$B$13,2),0) -> 45536560 | I13: =IFERROR(H13/SUM(Category_Analysis!$B$4:$B$13),0) -> 0.1605079
A14: IT | B14: =Budget_vs_Actual!B7 -> 22000000 | C14: =Budget_vs_Actual!G7 -> 17507714 | D14: =Budget_vs_Actual!H7 -> -4492286 | E14: =Budget_vs_Actual!J7 -> ❌ Over Budget | G14: =IFERROR(INDEX(Category_Analysis!$A$4:$A$13,MATCH(LARGE(Category_Analysis!$B$4:$B$13,3),Category_Analysis!$B$4:$B$13,0)),"N/A") -> Software Licenses | H14: =IFERROR(LARGE(Category_Analysis!$B$4:$B$13,3),0) -> 42970528 | I14: =IFERROR(H14/SUM(Category_Analysis!$B$4:$B$13),0) -> 0.15146312
A15: HR | B15: =Budget_vs_Actual!B8 -> 18500000 | C15: =Budget_vs_Actual!G8 -> 16868476 | D15: =Budget_vs_Actual!H8 -> -1631524 | E15: =Budget_vs_Actual!J8 -> ⚠️ Near Limit
A16: Finance | B16: =Budget_vs_Actual!B9 -> 15000000 | C16: =Budget_vs_Actual!G9 -> 15388066 | D16: =Budget_vs_Actual!H9 -> 388066 | E16: =Budget_vs_Actual!J9 -> ✅ Under Budget
A17: Marketing | B17: =Budget_vs_Actual!B10 -> 25000000 | C17: =Budget_vs_Actual!G10 -> 24512746 | D17: =Budget_vs_Actual!H10 -> -487254 | E17: =Budget_vs_Actual!J10 -> ⚠️ Near Limit
A18: TOTAL | B18: =SUM(Budget_vs_Actual!B5:B10) -> 163500000 | C18: =SUM(Budget_vs_Actual!G5:G10) -> 147196032 | D18: =SUM(Budget_vs_Actual!H5:H10) -> -16303968
A20: KEY INSIGHTS
A21: 💡 Marketing and Sales departments show the highest overspend risk — exceeding 95% of allocated budget by Q3. Recommend budget review for FY2025. | G21: ✅ Finance and HR departments consistently operated within budget, with combined savings of ~₦3.2M — a model for cost discipline across other units.

Sheet Raw_Transactions
A1: Trans_ID | B1: Date | C1: Department | D1: Category | E1: Description | F1: Amount (NGN) | G1: Approved_By | H1: Status | I1: Notes
A2: TXN-1001 | B2: 05/04/2024 | C2: Operations | D2: Salaries | E2: Contract staff pay | F2: 1248506.5 | G2: Chukwu A. | H2: Approved
A3: TXN-1002 | B3: 20/09/2024 | C3: Sales | D3: Salaries | E3: Monthly staff salaries | F3: 995591.32 | G3: Chukwu A. | H3: Pending
A4: TXN-1003 | B4: 26/05/2024 | C4: IT | D4: Utilities | E4: Electricity bill | F4: 2029702.6 | G4: Chukwu A. | H4: Approved
A5: TXN-1004 | B5: 04/06/2024 | C5: Marketing | D5: Training | E5: Excel training workshop | F5: 980682.22 | G5: Chukwu A. | H5: approved | I5: Duplicate check
A6: TXN-1005 | B6: 04/09/2024 | C6: Finance | D6: Training | E6: Excel training workshop | F6: 3287847.1 | G6: Nwachukwu F. | H6: Approved
A7: TXN-1006 | B7: 02/02/2024 | C7: Finance | D7: Marketing | E7: Brand design | F7: 877414.33 | G7: Bello R. | H7: Rejected
A8: TXN-1007 | B8: 27/11/2024 | C8: HR | D8: Software Licenses | E8: Antivirus subscription | F8: 1261711.6 | G8: Adeyemi T. | H8: Approved
A9: TXN-1008 | B9: 03/11/2024 | C9: HR | D9: Training | E9: PMP certification | F9: 4215895.8 | G9: Okafor M. | H9: Approved
A10: TXN-1009 | B10: 23/11/2024 | C10: HR | D10: Travel & Transport | E10: Airport transfer | F10: 1716857.7 | G10: Okafor M. | H10: Pending
A11: TXN-1010 | B11: 09/07/2024 | C11: Sales | D11: Office Supplies | E11: Printer cartridges | F11: 3625630.4 | G11: Chukwu A. | H11: Pending
A12: TXN-1011 | B12: 21/07/2024 | C12: Finance | D12: Marketing | E12: Social media ads | F12: 2954642.4 | G12: Nwachukwu F. | H12: Approved | I12: Needs resubmission
A13: TXN-1012 | B13: 19/07/2024 | C13: IT | D13: Equipment | E13: Projector | F13: 3365357 | G13: Nwachukwu F. | H13: Approved | I13: Needs resubmission
A14: TXN-1013 | B14: 05/02/2024 | C14: IT | D14: Consulting Fees | E14: IT audit consultant | F14: 3404683 | G14: Bello R. | H14: approved
A15: TXN-1014 | B15: 09/09/2024 | C15: OPERATIONS | D15: Utilities | E15: Generator maintenance | F15: 4482604.4 | G15: Okafor M. | H15: Approved
A16: TXN-1015 | B16: 04/06/2024 | C16: Operations | D16: Equipment | E16: Projector | F16: 3462165.3 | G16: Adeyemi T. | H16: approved | I16: Verify receipt
A17: TXN-1016 | B17: 28/02/2024 | C17: Finance | D17: Equipment | E17: Laptop purchase | F17: 2291952.3 | G17: Adeyemi T. | H17: Pending | I17: Needs resubmission
A18: TXN-1017 | B18: 01/08/2024 | C18: IT | D18: Equipment | E18: Laptop purchase | F18: 2701266.5 | G18: Chukwu A. | H18: Approved
A19: TXN-1018 | B19: 03/10/2024 | C19: Finance | D19: Office Supplies | E19: Printer cartridges | F19: 1095309.1 | G19: Chukwu A. | H19: APPROVED
A20: TXN-1019 | B20: 06/09/2024 | C20: IT | D20: Travel & Transport | E20: Client visit – Abuja | F20: 2973982.4 | G20: Adeyemi T. | H20: approved
A21: TXN-1020 | B21: 21/11/2024 | C21: IT | D21: Office Supplies | E21: Office furniture | F21: 1413047.6 | G21: Adeyemi T. | H21: APPROVED
A22: TXN-1021 | B22: 01/06/2024 | C22: sales | D22: Software Licenses | E22: Microsoft 365 renewal | F22: 1022767.6 | G22: Okafor M. | H22: Pending
A23: TXN-1022 | B23: 03/04/2024 | C23: Sales | D23: Software Licenses | E23: Accounting software | F23: 2845496.8 | G23: Chukwu A. | H23: Approved | I23: Needs resubmission
A24: TXN-1023 | B24: 19/12/2024 | C24: Finance | D24: Consulting Fees | E24: IT audit consultant | F24: 2433464.2 | G24: Okafor M. | H24: APPROVED | I24: OK
A25: TXN-1024 | B25: 12/07/2024 | C25: OPERATIONS | D25: Office Supplies | E25: Printer cartridges | F25: 449734.7 | G25: Nwachukwu F. | H25: approved
A26: TXN-1025 | B26: 26/06/2024 | C26: Sales | D26: Software Licenses | E26: Microsoft 365 renewal | F26: 1820756.4 | G26: Chukwu A. | H26: Pending | I26: OK
A27: TXN-1026 | B27: 28/04/2024 | C27: IT | D27: Utilities | E27: Electricity bill | F27: 1264275 | G27: Chukwu A. | H27: APPROVED
A28: TXN-1027 | B28: 27/09/2024 | C28: IT | D28: Software Licenses | E28: Microsoft 365 renewal | F28: 2939869.9 | G28: Chukwu A. | H28: Approved
A29: TXN-1028 | B29: 28/04/2024 | C29: HR | D29: Travel & Transport | E29: Airport transfer | F29: 2193100.5 | G29: Nwachukwu F. | H29: Approved | I29: Verify receipt
A30: TXN-1029 | B30: 24/12/2024 | C30: OPERATIONS | D30: Training | E30: Data analytics course | F30: 1294342.8 | G30: Okafor M. | H30: APPROVED | I30: Duplicate check
A31: TXN-1030 | B31: 24/01/2024 | C31: HR | D31: Salaries | E31: Contract staff pay | F31: 3314781.2 | G31: Adeyemi T. | H31: Approved | I31: OK
A32: TXN-1031 | B32: 03/09/2024 | C32: IT | D32: Equipment | E32: Laptop purchase | F32: 270104.92 | G32: Bello R. | H32: Approved
A33: TXN-1032 | B33: 08/10/2024 | C33: HR | D33: Utilities | E33: Electricity bill | F33: 4238058.6 | G33: Okafor M. | H33: Approved
A34: TXN-1033 | B34: 07/05/2024 | C34: OPERATIONS | D34: Miscellaneous | E34: Sundry items | F34: 2359680.5 | G34: Adeyemi T. | H34: Pending | I34: Needs resubmission
A35: TXN-1034 | B35: 01/02/2024 | C35: Finance | D35: Consulting Fees | E35: Legal advisory | F35: 4181647.2 | G35: Nwachukwu F. | H35: Approved | I35: Needs resubmission
A36: TXN-1035 | B36: 08/02/2024 | C36: IT | D36: Training | E36: Excel training workshop | F36: 4200668.3 | G36: Adeyemi T. | H36: Rejected | I36: Duplicate check
A37: TXN-1036 | B37: 10/09/2024 | C37: Finance | D37: Equipment | E37: Laptop purchase | F37: 3010366.5 | G37: Chukwu A. | H37: Approved | I37: Verify receipt
A38: TXN-1037 | B38: 23/04/2024 | C38: IT | D38: Travel & Transport | E38: Airport transfer | F38: 1278676.9 | G38: Adeyemi T. | H38: Pending
A39: TXN-1038 | B39: 03/01/2024 | C39: Finance | D39: Equipment | E39: Projector | F39: 1141278.8 | G39: Nwachukwu F. | H39: Rejected | I39: Duplicate check
A40: TXN-1039 | B40: 23/09/2024 | C40: IT | D40: Training | E40: Excel training workshop | F40: 3339420.6 | G40: Nwachukwu F. | H40: Approved | I40: Needs resubmission
...

Sheet Cleaned_Data
A1: Trans_ID | B1: Date | C1: Month | D1: Department (Clean) | E1: Category | F1: Description | G1: Amount (NGN) | H1: Approved_By | I1: Status (Clean) | J1: Quarter | L1: Raw Dept | M1: Clean Dept | O1: Raw Status | P1: Clean Status | R1: Month Num | S1: Month Name
A2: =Raw_Transactions!A2 -> TXN-1001 | B2: =Raw_Transactions!B2 -> 05/04/2024 | C2: =IFERROR(VALUE(MID(Raw_Transactions!B2,4,2)),"") -> 4 | D2: =IFERROR(xlookup(Raw_Transactions!C2,$L$2:$L$11,$M$2:$M$11,"Unknown"),"Unknown") -> Unknown | E2: =Raw_Transactions!D2 -> Salaries | F2: =Raw_Transactions!E2 -> Contract staff pay | G2: =Raw_Transactions!F2 -> 1248506.5 | H2: =Raw_Transactions!G2 -> Chukwu A. | I2: =IFERROR(xlookup(Raw_Transactions!H2,$O$2:$O$6,$P$2:$P$6,"Unknown"),"Unknown") -> Unknown | J2: =IF(C2<=3,"Q1",IF(C2<=6,"Q2",IF(C2<=9,"Q3","Q4"))) -> Q2 | L2: Sales | M2: Sales | O2: Approved | P2: Approved | R2: 1 | S2: Jan
A3: =Raw_Transactions!A3 -> TXN-1002 | B3: =Raw_Transactions!B3 -> 20/09/2024 | C3: =IFERROR(VALUE(MID(Raw_Transactions!B3,4,2)),"") -> 9 | D3: =IFERROR(xlookup(Raw_Transactions!C3,$L$2:$L$11,$M$2:$M$11,"Unknown"),"Unknown") -> Unknown | E3: =Raw_Transactions!D3 -> Salaries | F3: =Raw_Transactions!E3 -> Monthly staff salaries | G3: =Raw_Transactions!F3 -> 995591.32 | H3: =Raw_Transactions!G3 -> Chukwu A. | I3: =IFERROR(xlookup(Raw_Transactions!H3,$O$2:$O$6,$P$2:$P$6,"Unknown"),"Unknown") -> Unknown | J3: =IF(C3<=3,"Q1",IF(C3<=6,"Q2",IF(C3<=9,"Q3","Q4"))) -> Q3 | L3: Operations | M3: Operations | O3: approved | P3: Approved | R3: 2 | S3: Feb
A4: =Raw_Transactions!A4 -> TXN-1003 | B4: =Raw_Transactions!B4 -> 26/05/2024 | C4: =IFERROR(VALUE(MID(Raw_Transactions!B4,4,2)),"") -> 5 | D4: =IFERROR(xlookup(Raw_Transactions!C4,$L$2:$L$11,$M$2:$M$11,"Unknown"),"Unknown") -> Unknown | E4: =Raw_Transactions!D4 -> Utilities | F4: =Raw_Transactions!E4 -> Electricity bill | G4: =Raw_Transactions!F4 -> 2029702.6 | H4: =Raw_Transactions!G4 -> Chukwu A. | I4: =IFERROR(xlookup(Raw_Transactions!H4,$O$2:$O$6,$P$2:$P$6,"Unknown"),"Unknown") -> Unknown | J4: =IF(C4<=3,"Q1",IF(C4<=6,"Q2",IF(C4<=9,"Q3","Q4"))) -> Q2 | L4: IT | M4: IT | O4: APPROVED | P4: Approved | R4: 3 | S4: Mar
A5: =Raw_Transactions!A5 -> TXN-1004 | B5: =Raw_Transactions!B5 -> 04/06/2024 | C5: =IFERROR(VALUE(MID(Raw_Transactions!B5,4,2)),"") -> 6 | D5: =IFERROR(xlookup(Raw_Transactions!C5,$L$2:$L$11,$M$2:$M$11,"Unknown"),"Unknown") -> Unknown | E5: =Raw_Transactions!D5 -> Training | F5: =Raw_Transactions!E5 -> Excel training workshop | G5: =Raw_Transactions!F5 -> 980682.22 | H5: =Raw_Transactions!G5 -> Chukwu A. | I5: =IFERROR(xlookup(Raw_Transactions!H5,$O$2:$O$6,$P$2:$P$6,"Unknown"),"Unknown") -> Unknown | J5: =IF(C5<=3,"Q1",IF(C5<=6,"Q2",IF(C5<=9,"Q3","Q4"))) -> Q2 | L5: HR | M5: HR | O5: Pending | P5: Pending | R5: 4 | S5: Apr
A6: =Raw_Transactions!A6 -> TXN-1005 | B6: =Raw_Transactions!B6 -> 04/09/2024 | C6: =IFERROR(VALUE(MID(Raw_Transactions!B6,4,2)),"") -> 9 | D6: =IFERROR(xlookup(Raw_Transactions!C6,$L$2:$L$11,$M$2:$M$11,"Unknown"),"Unknown") -> Unknown | E6: =Raw_Transactions!D6 -> Training | F6: =Raw_Transactions!E6 -> Excel training workshop | G6: =Raw_Transactions!F6 -> 3287847.1 | H6: =Raw_Transactions!G6 -> Nwachukwu F. | I6: =IFERROR(xlookup(Raw_Transactions!H6,$O$2:$O$6,$P$2:$P$6,"Unknown"),"Unknown") -> Unknown | J6: =IF(C6<=3,"Q1",IF(C6<=6,"Q2",IF(C6<=9,"Q3","Q4"))) -> Q3 | L6: Finance | M6: Finance | O6: Rejected | P6: Rejected | R6: 5 | S6: May
A7: =Raw_Transactions!A7 -> TXN-1006 | B7: =Raw_Transactions!B7 -> 02/02/2024 | C7: =IFERROR(VALUE(MID(Raw_Transactions!B7,4,2)),"") -> 2 | D7: =IFERROR(xlookup(Raw_Transactions!C7,$L$2:$L$11,$M$2:$M$11,"Unknown"),"Unknown") -> Unknown | E7: =Raw_Transactions!D7 -> Marketing | F7: =Raw_Transactions!E7 -> Brand design | G7: =Raw_Transactions!F7 -> 877414.33 | H7: =Raw_Transactions!G7 -> Bello R. | I7: =IFERROR(xlookup(Raw_Transactions!H7,$O$2:$O$6,$P$2:$P$6,"Unknown"),"Unknown") -> Unknown | J7: =IF(C7<=3,"Q1",IF(C7<=6,"Q2",IF(C7<=9,"Q3","Q4"))) -> Q1 | L7: Marketing | M7: Marketing | R7: 6 | S7: Jun
A8: =Raw_Transactions!A8 -> TXN-1007 | B8: =Raw_Transactions!B8 -> 27/11/2024 | C8: =IFERROR(VALUE(MID(Raw_Transactions!B8,4,2)),"") -> 11 | D8: =IFERROR(xlookup(Raw_Transactions!C8,$L$2:$L$11,$M$2:$M$11,"Unknown"),"Unknown") -> Unknown | E8: =Raw_Transactions!D8 -> Software Licenses | F8: =Raw_Transactions!E8 -> Antivirus subscription | G8: =Raw_Transactions!F8 -> 1261711.6 | H8: =Raw_Transactions!G8 -> Adeyemi T. | I8: =IFERROR(xlookup(Raw_Transactions!H8,$O$2:$O$6,$P$2:$P$6,"Unknown"),"Unknown") -> Unknown | J8: =IF(C8<=3,"Q1",IF(C8<=6,"Q2",IF(C8<=9,"Q3","Q4"))) -> Q4 | L8: OPERATIONS | M8: Operations | R8: 7 | S8: Jul
A9: =Raw_Transactions!A9 -> TXN-1008 | B9: =Raw_Transactions!B9 -> 03/11/2024 | C9: =IFERROR(VALUE(MID(Raw_Transactions!B9,4,2)),"") -> 11 | D9: =IFERROR(xlookup(Raw_Transactions!C9,$L$2:$L$11,$M$2:$M$11,"Unknown"),"Unknown") -> Unknown | E9: =Raw_Transactions!D9 -> Training | F9: =Raw_Transactions!E9 -> PMP certification | G9: =Raw_Transactions!F9 -> 4215895.8 | H9: =Raw_Transactions!G9 -> Okafor M. | I9: =IFERROR(xlookup(Raw_Transactions!H9,$O$2:$O$6,$P$2:$P$6,"Unknown"),"Unknown") -> Unknown | J9: =IF(C9<=3,"Q1",IF(C9<=6,"Q2",IF(C9<=9,"Q3","Q4"))) -> Q4 | L9: sales | M9: Sales | R9: 8 | S9: Aug
A10: =Raw_Transactions!A10 -> TXN-1009 | B10: =Raw_Transactions!B10 -> 23/11/2024 | C10: =IFERROR(VALUE(MID(Raw_Transactions!B10,4,2)),"") -> 11 | D10: =IFERROR(xlookup(Raw_Transactions!C10,$L$2:$L$11,$M$2:$M$11,"Unknown"),"Unknown") -> Unknown | E10: =Raw_Transactions!D10 -> Travel & Transport | F10: =Raw_Transactions!E10 -> Airport transfer | G10: =Raw_Transactions!F10 -> 1716857.7 | H10: =Raw_Transactions!G10 -> Okafor M. | I10: =IFERROR(xlookup(Raw_Transactions!H10,$O$2:$O$6,$P$2:$P$6,"Unknown"),"Unknown") -> Unknown | J10: =IF(C10<=3,"Q1",IF(C10<=6,"Q2",IF(C10<=9,"Q3","Q4"))) -> Q4 | L10: IT | M10: IT | R10: 9 | S10: Sep
A11: =Raw_Transactions!A11 -> TXN-1010 | B11: =Raw_Transactions!B11 -> 09/07/2024 | C11: =IFERROR(VALUE(MID(Raw_Transactions!B11,4,2)),"") -> 7 | D11: =IFERROR(xlookup(Raw_Transactions!C11,$L$2:$L$11,$M$2:$M$11,"Unknown"),"Unknown") -> Unknown | E11: =Raw_Transactions!D11 -> Office Supplies | F11: =Raw_Transactions!E11 -> Printer cartridges | G11: =Raw_Transactions!F11 -> 3625630.4 | H11: =Raw_Transactions!G11 -> Chukwu A. | I11: =IFERROR(xlookup(Raw_Transactions!H11,$O$2:$O$6,$P$2:$P$6,"Unknown"),"Unknown") -> Unknown | J11: =IF(C11<=3,"Q1",IF(C11<=6,"Q2",IF(C11<=9,"Q3","Q4"))) -> Q3 | L11: Finance | M11: Finance | R11: 10 | S11: Oct
A12: =Raw_Transactions!A12 -> TXN-1011 | B12: =Raw_Transactions!B12 -> 21/07/2024 | C12: =IFERROR(VALUE(MID(Raw_Transactions!B12,4,2)),"") -> 7 | D12: =IFERROR(xlookup(Raw_Transactions!C12,$L$2:$L$11,$M$2:$M$11,"Unknown"),"Unknown") -> Unknown | E12: =Raw_Transactions!D12 -> Marketing | F12: =Raw_Transactions!E12 -> Social media ads | G12: =Raw_Transactions!F12 -> 2954642.4 | H12: =Raw_Transactions!G12 -> Nwachukwu F. | I12: =IFERROR(xlookup(Raw_Transactions!H12,$O$2:$O$6,$P$2:$P$6,"Unknown"),"Unknown") -> Unknown | J12: =IF(C12<=3,"Q1",IF(C12<=6,"Q2",IF(C12<=9,"Q3","Q4"))) -> Q3 | R12: 11 | S12: Nov
A13: =Raw_Transactions!A13 -> TXN-1012 | B13: =Raw_Transactions!B13 -> 19/07/2024 | C13: =IFERROR(VALUE(MID(Raw_Transactions!B13,4,2)),"") -> 7 | D13: =IFERROR(xlookup(Raw_Transactions!C13,$L$2:$L$11,$M$2:$M$11,"Unknown"),"Unknown") -> Unknown | E13: =Raw_Transactions!D13 -> Equipment | F13: =Raw_Transactions!E13 -> Projector | G13: =Raw_Transactions!F13 -> 3365357 | H13: =Raw_Transactions!G13 -> Nwachukwu F. | I13: =IFERROR(xlookup(Raw_Transactions!H13,$O$2:$O$6,$P$2:$P$6,"Unknown"),"Unknown") -> Unknown | J13: =IF(C13<=3,"Q1",IF(C13<=6,"Q2",IF(C13<=9,"Q3","Q4"))) -> Q3 | R13: 12 | S13: Dec
A14: =Raw_Transactions!A14 -> TXN-1013 | B14: =Raw_Transactions!B14 -> 05/02/2024 | C14: =IFERROR(VALUE(MID(Raw_Transactions!B14,4,2)),"") -> 2 | D14: =IFERROR(xlookup(Raw_Transactions!C14,$L$2:$L$11,$M$2:$M$11,"Unknown"),"Unknown") -> Unknown | E14: =Raw_Transactions!D14 -> Consulting Fees | F14: =Raw_Transactions!E14 -> IT audit consultant | G14: =Raw_Transactions!F14 -> 3404683 | H14: =Raw_Transactions!G14 -> Bello R. | I14: =IFERROR(xlookup(Raw_Transactions!H14,$O$2:$O$6,$P$2:$P$6,"Unknown"),"Unknown") -> Unknown | J14: =IF(C14<=3,"Q1",IF(C14<=6,"Q2",IF(C14<=9,"Q3","Q4"))) -> Q1
A15: =Raw_Transactions!A15 -> TXN-1014 | B15: =Raw_Transactions!B15 -> 09/09/2024 | C15: =IFERROR(VALUE(MID(Raw_Transactions!B15,4,2)),"") -> 9 | D15: =IFERROR(xlookup(Raw_Transactions!C15,$L$2:$L$11,$M$2:$M$11,"Unknown"),"Unknown") -> Unknown | E15: =Raw_Transactions!D15 -> Utilities | F15: =Raw_Transactions!E15 -> Generator maintenance | G15: =Raw_Transactions!F15 -> 4482604.4 | H15: =Raw_Transactions!G15 -> Okafor M. | I15: =IFERROR(xlookup(Raw_Transactions!H15,$O$2:$O$6,$P$2:$P$6,"Unknown"),"Unknown") -> Unknown | J15: =IF(C15<=3,"Q1",IF(C15<=6,"Q2",IF(C15<=9,"Q3","Q4"))) -> Q3
A16: =Raw_Transactions!A16 -> TXN-1015 | B16: =Raw_Transactions!B16 -> 04/06/2024 | C16: =IFERROR(VALUE(MID(Raw_Transactions!B16,4,2)),"") -> 6 | D16: =IFERROR(xlookup(Raw_Transactions!C16,$L$2:$L$11,$M$2:$M$11,"Unknown"),"Unknown") -> Unknown | E16: =Raw_Transactions!D16 -> Equipment | F16: =Raw_Transactions!E16 -> Projector | G16: =Raw_Transactions!F16 -> 3462165.3 | H16: =Raw_Transactions!G16 -> Adeyemi T. | I16: =IFERROR(xlookup(Raw_Transactions!H16,$O$2:$O$6,$P$2:$P$6,"Unknown"),"Unknown") -> Unknown | J16: =IF(C16<=3,"Q1",IF(C16<=6,"Q2",IF(C16<=9,"Q3","Q4"))) -> Q2
A17: =Raw_Transactions!A17 -> TXN-1016 | B17: =Raw_Transactions!B17 -> 28/02/2024 | C17: =IFERROR(VALUE(MID(Raw_Transactions!B17,4,2)),"") -> 2 | D17: =IFERROR(xlookup(Raw_Transactions!C17,$L$2:$L$11,$M$2:$M$11,"Unknown"),"Unknown") -> Unknown | E17: =Raw_Transactions!D17 -> Equipment | F17: =Raw_Transactions!E17 -> Laptop purchase | G17: =Raw_Transactions!F17 -> 2291952.3 | H17: =Raw_Transactions!G17 -> Adeyemi T. | I17: =IFERROR(xlookup(Raw_Transactions!H17,$O$2:$O$6,$P$2:$P$6,"Unknown"),"Unknown") -> Unknown | J17: =IF(C17<=3,"Q1",IF(C17<=6,"Q2",IF(C17<=9,"Q3","Q4"))) -> Q1
A18: =Raw_Transactions!A18 -> TXN-1017 | B18: =Raw_Transactions!B18 -> 01/08/2024 | C18: =IFERROR(VALUE(MID(Raw_Transactions!B18,4,2)),"") -> 8 | D18: =IFERROR(xlookup(Raw_Transactions!C18,$L$2:$L$11,$M$2:$M$11,"Unknown"),"Unknown") -> Unknown | E18: =Raw_Transactions!D18 -> Equipment | F18: =Raw_Transactions!E18 -> Laptop purchase | G18: =Raw_Transactions!F18 -> 2701266.5 | H18: =Raw_Transactions!G18 -> Chukwu A. | I18: =IFERROR(xlookup(Raw_Transactions!H18,$O$2:$O$6,$P$2:$P$6,"Unknown"),"Unknown") -> Unknown | J18: =IF(C18<=3,"Q1",IF(C18<=6,"Q2",IF(C18<=9,"Q3","Q4"))) -> Q3
A19: =Raw_Transactions!A19 -> TXN-1018 | B19: =Raw_Transactions!B19 -> 03/10/2024 | C19: =IFERROR(VALUE(MID(Raw_Transactions!B19,4,2)),"") -> 10 | D19: =IFERROR(xlookup(Raw_Transactions!C19,$L$2:$L$11,$M$2:$M$11,"Unknown"),"Unknown") -> Unknown | E19: =Raw_Transactions!D19 -> Office Supplies | F19: =Raw_Transactions!E19 -> Printer cartridges | G19: =Raw_Transactions!F19 -> 1095309.1 | H19: =Raw_Transactions!G19 -> Chukwu A. | I19: =IFERROR(xlookup(Raw_Transactions!H19,$O$2:$O$6,$P$2:$P$6,"Unknown"),"Unknown") -> Unknown | J19: =IF(C19<=3,"Q1",IF(C19<=6,"Q2",IF(C19<=9,"Q3","Q4"))) -> Q4
A20: =Raw_Transactions!A20 -> TXN-1019 | B20: =Raw_Transactions!B20 -> 06/09/2024 | C20: =IFERROR(VALUE(MID(Raw_Transactions!B20,4,2)),"") -> 9 | D20: =IFERROR(xlookup(Raw_Transactions!C20,$L$2:$L$11,$M$2:$M$11,"Unknown"),"Unknown") -> Unknown | E20: =Raw_Transactions!D20 -> Travel & Transport | F20: =Raw_Transactions!E20 -> Client visit – Abuja | G20: =Raw_Transactions!F20 -> 2973982.4 | H20: =Raw_Transactions!G20 -> Adeyemi T. | I20: =IFERROR(xlookup(Raw_Transactions!H20,$O$2:$O$6,$P$2:$P$6,"Unknown"),"Unknown") -> Unknown | J20: =IF(C20<=3,"Q1",IF(C20<=6,"Q2",IF(C20<=9,"Q3","Q4"))) -> Q3
A21: =Raw_Transactions!A21 -> TXN-1020 | B21: =Raw_Transactions!B21 -> 21/11/2024 | C21: =IFERROR(VALUE(MID(Raw_Transactions!B21,4,2)),"") -> 11 | D21: =IFERROR(xlookup(Raw_Transactions!C21,$L$2:$L$11,$M$2:$M$11,"Unknown"),"Unknown") -> Unknown | E21: =Raw_Transactions!D21 -> Office Supplies | F21: =Raw_Transactions!E21 -> Office furniture | G21: =Raw_Transactions!F21 -> 1413047.6 | H21: =Raw_Transactions!G21 -> Adeyemi T. | I21: =IFERROR(xlookup(Raw_Transactions!H21,$O$2:$O$6,$P$2:$P$6,"Unknown"),"Unknown") -> Unknown | J21: =IF(C21<=3,"Q1",IF(C21<=6,"Q2",IF(C21<=9,"Q3","Q4"))) -> Q4
A22: =Raw_Transactions!A22 -> TXN-1021 | B22: =Raw_Transactions!B22 -> 01/06/2024 | C22: =IFERROR(VALUE(MID(Raw_Transactions!B22,4,2)),"") -> 6 | D22: =IFERROR(xlookup(Raw_Transactions!C22,$L$2:$L$11,$M$2:$M$11,"Unknown"),"Unknown") -> Unknown | E22: =Raw_Transactions!D22 -> Software Licenses | F22: =Raw_Transactions!E22 -> Microsoft 365 renewal | G22: =Raw_Transactions!F22 -> 1022767.6 | H22: =Raw_Transactions!G22 -> Okafor M. | I22: =IFERROR(xlookup(Raw_Transactions!H22,$O$2:$O$6,$P$2:$P$6,"Unknown"),"Unknown") -> Unknown | J22: =IF(C22<=3,"Q1",IF(C22<=6,"Q2",IF(C22<=9,"Q3","Q4"))) -> Q2
A23: =Raw_Transactions!A23 -> TXN-1022 | B23: =Raw_Transactions!B23 -> 03/04/2024 | C23: =IFERROR(VALUE(MID(Raw_Transactions!B23,4,2)),"") -> 4 | D23: =IFERROR(xlookup(Raw_Transactions!C23,$L$2:$L$11,$M$2:$M$11,"Unknown"),"Unknown") -> Unknown | E23: =Raw_Transactions!D23 -> Software Licenses | F23: =Raw_Transactions!E23 -> Accounting software | G23: =Raw_Transactions!F23 -> 2845496.8 | H23: =Raw_Transactions!G23 -> Chukwu A. | I23: =IFERROR(xlookup(Raw_Transactions!H23,$O$2:$O$6,$P$2:$P$6,"Unknown"),"Unknown") -> Unknown | J23: =IF(C23<=3,"Q1",IF(C23<=6,"Q2",IF(C23<=9,"Q3","Q4"))) -> Q2
A24: =Raw_Transactions!A24 -> TXN-1023 | B24: =Raw_Transactions!B24 -> 19/12/2024 | C24: =IFERROR(VALUE(MID(Raw_Transactions!B24,4,2)),"") -> 12 | D24: =IFERROR(xlookup(Raw_Transactions!C24,$L$2:$L$11,$M$2:$M$11,"Unknown"),"Unknown") -> Unknown | E24: =Raw_Transactions!D24 -> Consulting Fees | F24: =Raw_Transactions!E24 -> IT audit consultant | G24: =Raw_Transactions!F24 -> 2433464.2 | H24: =Raw_Transactions!G24 -> Okafor M. | I24: =IFERROR(xlookup(Raw_Transactions!H24,$O$2:$O$6,$P$2:$P$6,"Unknown"),"Unknown") -> Unknown | J24: =IF(C24<=3,"Q1",IF(C24<=6,"Q2",IF(C24<=9,"Q3","Q4"))) -> Q4
A25: =Raw_Transactions!A25 -> TXN-1024 | B25: =Raw_Transactions!B25 -> 12/07/2024 | C25: =IFERROR(VALUE(MID(Raw_Transactions!B25,4,2)),"") -> 7 | D25: =IFERROR(xlookup(Raw_Transactions!C25,$L$2:$L$11,$M$2:$M$11,"Unknown"),"Unknown") -> Unknown | E25: =Raw_Transactions!D25 -> Office Supplies | F25: =Raw_Transactions!E25 -> Printer cartridges | G25: =Raw_Transactions!F25 -> 449734.7 | H25: =Raw_Transactions!G25 -> Nwachukwu F. | I25: =IFERROR(xlookup(Raw_Transactions!H25,$O$2:$O$6,$P$2:$P$6,"Unknown"),"Unknown") -> Unknown | J25: =IF(C25<=3,"Q1",IF(C25<=6,"Q2",IF(C25<=9,"Q3","Q4"))) -> Q3
... A121: =Raw_Transactions!A121 -> TXN-1120 | B121: =Raw_Transactions!B121 -> 19/06/2024 | C121: =IFERROR(VALUE(MID(Raw_Transactions!B121,4,2)),"") -> 6 | D121: =IFERROR(xlookup(Raw_Transactions!C121,$L$2:$L$11,$M$2:$M$11,"Unknown"),"Unknown") -> Unknown | E121: =Raw_Transactions!D121 -> Software Licenses | F121: =Raw_Transactions!E121 -> Microsoft 365 renewal | G121: =Raw_Transactions!F121 -> 1725418.9 | H121: =Raw_Transactions!G121 -> Adeyemi T. | I121: =IFERROR(xlookup(Raw_Transactions!H121,$O$2:$O$6,$P$2:$P$6,"Unknown"),"Unknown") -> Unknown | J121: =IF(C121<=3,"Q1",IF(C121<=6,"Q2",IF(C121<=9,"Q3","Q4"))) -> Q2

Sheet Budget_vs_Actual
A1: BUDGET vs ACTUAL ANALYSIS — FY 2024
A2: Annual departmental spend tracked against approved budget | Currency: Nigerian Naira (NGN)
A4: Department | B4: Annual Budget (NGN) | C4: Q1 Actual | D4: Q2 Actual | E4: Q3 Actual | F4: Q4 Actual | G4: Total Actual (NGN) | H4: Variance (NGN) | I4: Variance % | J4: Status
A5: Sales | B5: 45000000 | C5: 9848697 | D5: 8914586 | E5: 11615046 | F5: 8491156 | G5: =SUM(C5:F5) -> 38869485 | H5: =G5-B5 -> -6130515 | I5: =IFERROR(H5/B5,0) -> -0.13623367 | J5: =IF(H5>=0,"✅ Under Budget",IF(H5>=-B5*0.1,"⚠️ Near Limit","❌ Over Budget")) -> ❌ Over Budget
A6: Operations | B6: 38000000 | C6: 9283622 | D6: 8507541 | E6: 7104475 | F6: 9153907 | G6: =SUM(C6:F6) -> 34049545 | H6: =G6-B6 -> -3950455 | I6: =IFERROR(H6/B6,0) -> -0.10395934 | J6: =IF(H6>=0,"✅ Under Budget",IF(H6>=-B6*0.1,"⚠️ Near Limit","❌ Over Budget")) -> ❌ Over Budget
A7: IT | B7: 22000000 | C7: 4058989 | D7: 5104825 | E7: 4144418 | F7: 4199482 | G7: =SUM(C7:F7) -> 17507714 | H7: =G7-B7 -> -4492286 | I7: =IFERROR(H7/B7,0) -> -0.20419482 | J7: =IF(H7>=0,"✅ Under Budget",IF(H7>=-B7*0.1,"⚠️ Near Limit","❌ Over Budget")) -> ❌ Over Budget
A8: HR | B8: 18500000 | C8: 4272433 | D8: 5165612 | E8: 3604840 | F8: 3825591 | G8: =SUM(C8:F8) -> 16868476 | H8: =G8-B8 -> -1631524 | I8: =IFERROR(H8/B8,0) -> -0.088190486 | J8: =IF(H8>=0,"✅ Under Budget",IF(H8>=-B8*0.1,"⚠️ Near Limit","❌ Over Budget")) -> ⚠️ Near Limit
A9: Finance | B9: 15000000 | C9: 3829380 | D9: 4405876 | E9: 3738785 | F9: 3414025 | G9: =SUM(C9:F9) -> 15388066 | H9: =G9-B9 -> 388066 | I9: =IFERROR(H9/B9,0) -> 0.025871067 | J9: =IF(H9>=0,"✅ Under Budget",IF(H9>=-B9*0.1,"⚠️ Near Limit","❌ Over Budget")) -> ✅ Under Budget
A10: Marketing | B10: 25000000 | C10: 7428765 | D10: 4639748 | E10: 7075405 | F10: 5368828 | G10: =SUM(C10:F10) -> 24512746 | H10: =G10-B10 -> -487254 | I10: =IFERROR(H10/B10,0) -> -0.01949016 | J10: =IF(H10>=0,"✅ Under Budget",IF(H10>=-B10*0.1,"⚠️ Near Limit","❌ Over Budget")) -> ⚠️ Near Limit
A11: TOTAL | B11: =SUM(B5:B10) -> 163500000 | C11: =SUM(C5:C10) -> 38721886 | D11: =SUM(D5:D10) -> 36738188 | E11: =SUM(E5:E10) -> 37282969 | F11: =SUM(F5:F10) -> 34452989 | G11: =SUM(G5:G10) -> 147196032 | H11: =SUM(H5:H10) -> -16303968 | I11: =SUM(I5:I10) -> -0.52619741

Sheet Monthly_Trend
A1: MONTHLY EXPENDITURE TREND — FY 2024
A3: Department | B3: Jan | C3: Feb | D3: Mar | E3: Apr | F3: May | G3: Jun | H3: Jul | I3: Aug | J3: Sep | K3: Oct | L3: Nov | M3: Dec | N3: Total | O3: Avg/Month | P3: Peak Month
A4: Sales | B4: =IFERROR(SUMIFS(Cleaned_Data!G$2:G$121,Cleaned_Data!D$2:D$121,A4,Cleaned_Data!C$2:C$121,1),0) -> 0 | C4: =IFERROR(SUMIFS(Cleaned_Data!G$2:G$121,Cleaned_Data!D$2:D$121,A4,Cleaned_Data!C$2:C$121,2),0) -> 0 | D4: =IFERROR(SUMIFS(Cleaned_Data!G$2:G$121,Cleaned_Data!D$2:D$121,A4,Cleaned_Data!C$2:C$121,3),0) -> 0 | E4: =IFERROR(SUMIFS(Cleaned_Data!G$2:G$121,Cleaned_Data!D$2:D$121,A4,Cleaned_Data!C$2:C$121,4),0) -> 0 | F4: =IFERROR(SUMIFS(Cleaned_Data!G$2:G$121,Cleaned_Data!D$2:D$121,A4,Cleaned_Data!C$2:C$121,5),0) -> 0 | G4: =IFERROR(SUMIFS(Cleaned_Data!G$2:G$121,Cleaned_Data!D$2:D$121,A4,Cleaned_Data!C$2:C$121,6),0) -> 0 | H4: =IFERROR(SUMIFS(Cleaned_Data!G$2:G$121,Cleaned_Data!D$2:D$121,A4,Cleaned_Data!C$2:C$121,7),0) -> 0 | I4: =IFERROR(SUMIFS(Cleaned_Data!G$2:G$121,Cleaned_Data!D$2:D$121,A4,Cleaned_Data!C$2:C$121,8),0) -> 0 | J4: =IFERROR(SUMIFS(Cleaned_Data!G$2:G$121,Cleaned_Data!D$2:D$121,A4,Cleaned_Data!C$2:C$121,9),0) -> 0 | K4: =IFERROR(SUMIFS(Cleaned_Data!G$2:G$121,Cleaned_Data!D$2:D$121,A4,Cleaned_Data!C$2:C$121,10),0) -> 0 | L4: =IFERROR(SUMIFS(Cleaned_Data!G$2:G$121,Cleaned_Data!D$2:D$121,A4,Cleaned_Data!C$2:C$121,11),0) -> 0 | M4: =IFERROR(SUMIFS(Cleaned_Data!G$2:G$121,Cleaned_Data!D$2:D$121,A4,Cleaned_Data!C$2:C$121,12),0) -> 0 | N4: =SUM(B4:M4) -> 0 | O4: =IFERROR(N4/COUNTIF(B4:M4,">0"),0) -> 0 | P4: =IFERROR(INDEX($B$3:$M$3,MATCH(MAX(B4:M4),B4:M4,0)),"N/A") -> Jan
A5: Operations | B5: =IFERROR(SUMIFS(Cleaned_Data!G$2:G$121,Cleaned_Data!D$2:D$121,A5,Cleaned_Data!C$2:C$121,1),0) -> 0 | C5: =IFERROR(SUMIFS(Cleaned_Data!G$2:G$121,Cleaned_Data!D$2:D$121,A5,Cleaned_Data!C$2:C$121,2),0) -> 0 | D5: =IFERROR(SUMIFS(Cleaned_Data!G$2:G$121,Cleaned_Data!D$2:D$121,A5,Cleaned_Data!C$2:C$121,3),0) -> 0 | E5: =IFERROR(SUMIFS(Cleaned_Data!G$2:G$121,Cleaned_Data!D$2:D$121,A5,Cleaned_Data!C$2:C$121,4),0) -> 0 | F5: =IFERROR(SUMIFS(Cleaned_Data!G$2:G$121,Cleaned_Data!D$2:D$121,A5,Cleaned_Data!C$2:C$121,5),0) -> 0 | G5: =IFERROR(SUMIFS(Cleaned_Data!G$2:G$121,Cleaned_Data!D$2:D$121,A5,Cleaned_Data!C$2:C$121,6),0) -> 0 | H5: =IFERROR(SUMIFS(Cleaned_Data!G$2:G$121,Cleaned_Data!D$2:D$121,A5,Cleaned_Data!C$2:C$121,7),0) -> 0 | I5: =IFERROR(SUMIFS(Cleaned_Data!G$2:G$121,Cleaned_Data!D$2:D$121,A5,Cleaned_Data!C$2:C$121,8),0) -> 0 | J5: =IFERROR(SUMIFS(Cleaned_Data!G$2:G$121,Cleaned_Data!D$2:D$121,A5,Cleaned_Data!C$2:C$121,9),0) -> 0 | K5: =IFERROR(SUMIFS(Cleaned_Data!G$2:G$121,Cleaned_Data!D$2:D$121,A5,Cleaned_Data!C$2:C$121,10),0) -> 0 | L5: =IFERROR(SUMIFS(Cleaned_Data!G$2:G$121,Cleaned_Data!D$2:D$121,A5,Cleaned_Data!C$2:C$121,11),0) -> 0 | M5: =IFERROR(SUMIFS(Cleaned_Data!G$2:G$121,Cleaned_Data!D$2:D$121,A5,Cleaned_Data!C$2:C$121,12),0) -> 0 | N5: =SUM(B5:M5) -> 0 | O5: =IFERROR(N5/COUNTIF(B5:M5,">0"),0) -> 0 | P5: =IFERROR(INDEX($B$3:$M$3,MATCH(MAX(B5:M5),B5:M5,0)),"N/A") -> Jan
A6: IT | B6: =IFERROR(SUMIFS(Cleaned_Data!G$2:G$121,Cleaned_Data!D$2:D$121,A6,Cleaned_Data!C$2:C$121,1),0) -> 0 | C6: =IFERROR(SUMIFS(Cleaned_Data!G$2:G$121,Cleaned_Data!D$2:D$121,A6,Cleaned_Data!C$2:C$121,2),0) -> 0 | D6: =IFERROR(SUMIFS(Cleaned_Data!G$2:G$121,Cleaned_Data!D$2:D$121,A6,Cleaned_Data!C$2:C$121,3),0) -> 0 | E6: =IFERROR(SUMIFS(Cleaned_Data!G$2:G$121,Cleaned_Data!D$2:D$121,A6,Cleaned_Data!C$2:C$121,4),0) -> 0 | F6: =IFERROR(SUMIFS(Cleaned_Data!G$2:G$121,Cleaned_Data!D$2:D$121,A6,Cleaned_Data!C$2:C$121,5),0) -> 0 | G6: =IFERROR(SUMIFS(Cleaned_Data!G$2:G$121,Cleaned_Data!D$2:D$121,A6,Cleaned_Data!C$2:C$121,6),0) -> 0 | H6: =IFERROR(SUMIFS(Cleaned_Data!G$2:G$121,Cleaned_Data!D$2:D$121,A6,Cleaned_Data!C$2:C$121,7),0) -> 0 | I6: =IFERROR(SUMIFS(Cleaned_Data!G$2:G$121,Cleaned_Data!D$2:D$121,A6,Cleaned_Data!C$2:C$121,8),0) -> 0 | J6: =IFERROR(SUMIFS(Cleaned_Data!G$2:G$121,Cleaned_Data!D$2:D$121,A6,Cleaned_Data!C$2:C$121,9),0) -> 0 | K6: =IFERROR(SUMIFS(Cleaned_Data!G$2:G$121,Cleaned_Data!D$2:D$121,A6,Cleaned_Data!C$2:C$121,10),0) -> 0 | L6: =IFERROR(SUMIFS(Cleaned_Data!G$2:G$121,Cleaned_Data!D$2:D$121,A6,Cleaned_Data!C$2:C$121,11),0) -> 0 | M6: =IFERROR(SUMIFS(Cleaned_Data!G$2:G$121,Cleaned_Data!D$2:D$121,A6,Cleaned_Data!C$2:C$121,12),0) -> 0 | N6: =SUM(B6:M6) -> 0 | O6: =IFERROR(N6/COUNTIF(B6:M6,">0"),0) -> 0 | P6: =IFERROR(INDEX($B$3:$M$3,MATCH(MAX(B6:M6),B6:M6,0)),"N/A") -> Jan
A7: HR | B7: =IFERROR(SUMIFS(Cleaned_Data!G$2:G$121,Cleaned_Data!D$2:D$121,A7,Cleaned_Data!C$2:C$121,1),0) -> 0 | C7: =IFERROR(SUMIFS(Cleaned_Data!G$2:G$121,Cleaned_Data!D$2:D$121,A7,Cleaned_Data!C$2:C$121,2),0) -> 0 | D7: =IFERROR(SUMIFS(Cleaned_Data!G$2:G$121,Cleaned_Data!D$2:D$121,A7,Cleaned_Data!C$2:C$121,3),0) -> 0 | E7: =IFERROR(SUMIFS(Cleaned_Data!G$2:G$121,Cleaned_Data!D$2:D$121,A7,Cleaned_Data!C$2:C$121,4),0) -> 0 | F7: =IFERROR(SUMIFS(Cleaned_Data!G$2:G$121,Cleaned_Data!D$2:D$121,A7,Cleaned_Data!C$2:C$121,5),0) -> 0 | G7: =IFERROR(SUMIFS(Cleaned_Data!G$2:G$121,Cleaned_Data!D$2:D$121,A7,Cleaned_Data!C$2:C$121,6),0) -> 0 | H7: =IFERROR(SUMIFS(Cleaned_Data!G$2:G$121,Cleaned_Data!D$2:D$121,A7,Cleaned_Data!C$2:C$121,7),0) -> 0 | I7: =IFERROR(SUMIFS(Cleaned_Data!G$2:G$121,Cleaned_Data!D$2:D$121,A7,Cleaned_Data!C$2:C$121,8),0) -> 0 | J7: =IFERROR(SUMIFS(Cleaned_Data!G$2:G$121,Cleaned_Data!D$2:D$121,A7,Cleaned_Data!C$2:C$121,9),0) -> 0 | K7: =IFERROR(SUMIFS(Cleaned_Data!G$2:G$121,Cleaned_Data!D$2:D$121,A7,Cleaned_Data!C$2:C$121,10),0) -> 0 | L7: =IFERROR(SUMIFS(Cleaned_Data!G$2:G$121,Cleaned_Data!D$2:D$121,A7,Cleaned_Data!C$2:C$121,11),0) -> 0 | M7: =IFERROR(SUMIFS(Cleaned_Data!G$2:G$121,Cleaned_Data!D$2:D$121,A7,Cleaned_Data!C$2:C$121,12),0) -> 0 | N7: =SUM(B7:M7) -> 0 | O7: =IFERROR(N7/COUNTIF(B7:M7,">0"),0) -> 0 | P7: =IFERROR(INDEX($B$3:$M$3,MATCH(MAX(B7:M7),B7:M7,0)),"N/A") -> Jan
A8: Finance | B8: =IFERROR(SUMIFS(Cleaned_Data!G$2:G$121,Cleaned_Data!D$2:D$121,A8,Cleaned_Data!C$2:C$121,1),0) -> 0 | C8: =IFERROR(SUMIFS(Cleaned_Data!G$2:G$121,Cleaned_Data!D$2:D$121,A8,Cleaned_Data!C$2:C$121,2),0) -> 0 | D8: =IFERROR(SUMIFS(Cleaned_Data!G$2:G$121,Cleaned_Data!D$2:D$121,A8,Cleaned_Data!C$2:C$121,3),0) -> 0 | E8: =IFERROR(SUMIFS(Cleaned_Data!G$2:G$121,Cleaned_Data!D$2:D$121,A8,Cleaned_Data!C$2:C$121,4),0) -> 0 | F8: =IFERROR(SUMIFS(Cleaned_Data!G$2:G$121,Cleaned_Data!D$2:D$121,A8,Cleaned_Data!C$2:C$121,5),0) -> 0 | G8: =IFERROR(SUMIFS(Cleaned_Data!G$2:G$121,Cleaned_Data!D$2:D$121,A8,Cleaned_Data!C$2:C$121,6),0) -> 0 | H8: =IFERROR(SUMIFS(Cleaned_Data!G$2:G$121,Cleaned_Data!D$2:D$121,A8,Cleaned_Data!C$2:C$121,7),0) -> 0 | I8: =IFERROR(SUMIFS(Cleaned_Data!G$2:G$121,Cleaned_Data!D$2:D$121,A8,Cleaned_Data!C$2:C$121,8),0) -> 0 | J8: =IFERROR(SUMIFS(Cleaned_Data!G$2:G$121,Cleaned_Data!D$2:D$121,A8,Cleaned_Data!C$2:C$121,9),0) -> 0 | K8: =IFERROR(SUMIFS(Cleaned_Data!G$2:G$121,Cleaned_Data!D$2:D$121,A8,Cleaned_Data!C$2:C$121,10),0) -> 0 | L8: =IFERROR(SUMIFS(Cleaned_Data!G$2:G$121,Cleaned_Data!D$2:D$121,A8,Cleaned_Data!C$2:C$121,11),0) -> 0 | M8: =IFERROR(SUMIFS(Cleaned_Data!G$2:G$121,Cleaned_Data!D$2:D$121,A8,Cleaned_Data!C$2:C$121,12),0) -> 0 | N8: =SUM(B8:M8) -> 0 | O8: =IFERROR(N8/COUNTIF(B8:M8,">0"),0) -> 0 | P8: =IFERROR(INDEX($B$3:$M$3,MATCH(MAX(B8:M8),B8:M8,0)),"N/A") -> Jan
A9: Marketing | B9: =IFERROR(SUMIFS(Cleaned_Data!G$2:G$121,Cleaned_Data!D$2:D$121,A9,Cleaned_Data!C$2:C$121,1),0) -> 0 | C9: =IFERROR(SUMIFS(Cleaned_Data!G$2:G$121,Cleaned_Data!D$2:D$121,A9,Cleaned_Data!C$2:C$121,2),0) -> 0 | D9: =IFERROR(SUMIFS(Cleaned_Data!G$2:G$121,Cleaned_Data!D$2:D$121,A9,Cleaned_Data!C$2:C$121,3),0) -> 0 | E9: =IFERROR(SUMIFS(Cleaned_Data!G$2:G$121,Cleaned_Data!D$2:D$121,A9,Cleaned_Data!C$2:C$121,4),0) -> 0 | F9: =IFERROR(SUMIFS(Cleaned_Data!G$2:G$121,Cleaned_Data!D$2:D$121,A9,Cleaned_Data!C$2:C$121,5),0) -> 0 | G9: =IFERROR(SUMIFS(Cleaned_Data!G$2:G$121,Cleaned_Data!D$2:D$121,A9,Cleaned_Data!C$2:C$121,6),0) -> 0 | H9: =IFERROR(SUMIFS(Cleaned_Data!G$2:G$121,Cleaned_Data!D$2:D$121,A9,Cleaned_Data!C$2:C$121,7),0) -> 0 | I9: =IFERROR(SUMIFS(Cleaned_Data!G$2:G$121,Cleaned_Data!D$2:D$121,A9,Cleaned_Data!C$2:C$121,8),0) -> 0 | J9: =IFERROR(SUMIFS(Cleaned_Data!G$2:G$121,Cleaned_Data!D$2:D$121,A9,Cleaned_Data!C$2:C$121,9),0) -> 0 | K9: =IFERROR(SUMIFS(Cleaned_Data!G$2:G$121,Cleaned_Data!D$2:D$121,A9,Cleaned_Data!C$2:C$121,10),0) -> 0 | L9: =IFERROR(SUMIFS(Cleaned_Data!G$2:G$121,Cleaned_Data!D$2:D$121,A9,Cleaned_Data!C$2:C$121,11),0) -> 0 | M9: =IFERROR(SUMIFS(Cleaned_Data!G$2:G$121,Cleaned_Data!D$2:D$121,A9,Cleaned_Data!C$2:C$121,12),0) -> 0 | N9: =SUM(B9:M9) -> 0 | O9: =IFERROR(N9/COUNTIF(B9:M9,">0"),0) -> 0 | P9: =IFERROR(INDEX($B$3:$M$3,MATCH(MAX(B9:M9),B9:M9,0)),"N/A") -> Jan
A10: TOTAL | B10: =SUM(B4:B9) -> 0 | C10: =SUM(C4:C9) -> 0 | D10: =SUM(D4:D9) -> 0 | E10: =SUM(E4:E9) -> 0 | F10: =SUM(F4:F9) -> 0 | G10: =SUM(G4:G9) -> 0 | H10: =SUM(H4:H9) -> 0 | I10: =SUM(I4:I9) -> 0 | ... N10: =SUM(N4:N9) -> 0 | O10: =IFERROR(N10/12,0) -> 0

Sheet Category_Analysis
A1: EXPENDITURE BY CATEGORY — FY 2024
A3: Category | B3: Total Spend (NGN) | C3: % of Total | D3: Approved Only (NGN) | E3: Avg Transaction | F3: Count | G3: Priority Flag | I3: Category | J3: Priority
A4: Salaries | B4: =IFERROR(SUMIF(Cleaned_Data!E$2:E$121,A4,Cleaned_Data!G$2:G$121),0) -> 11942952 | C4: =IFERROR(B4/SUM($B$4:$B$13),0) -> 0.042096686 | D4: =IFERROR(SUMIFS(Cleaned_Data!G$2:G$121,Cleaned_Data!E$2:E$121,A4,Cleaned_Data!I$2:I$121,"Approved"),0) -> 0 | E4: =IFERROR(B4/COUNTIF(Cleaned_Data!E$2:E$121,A4),0) -> 1990492.1 | F4: =COUNTIF(Cleaned_Data!E$2:E$121,A4) -> 6 | G4: =IFERROR(VLOOKUP(A4,$I$4:$J$13,2,0),"N/A") -> High | I4: Salaries | J4: High
A5: Software Licenses | B5: =IFERROR(SUMIF(Cleaned_Data!E$2:E$121,A5,Cleaned_Data!G$2:G$121),0) -> 42970528 | C5: =IFERROR(B5/SUM($B$4:$B$13),0) -> 0.15146312 | D5: =IFERROR(SUMIFS(Cleaned_Data!G$2:G$121,Cleaned_Data!E$2:E$121,A5,Cleaned_Data!I$2:I$121,"Approved"),0) -> 0 | E5: =IFERROR(B5/COUNTIF(Cleaned_Data!E$2:E$121,A5),0) -> 2387251.5 | F5: =COUNTIF(Cleaned_Data!E$2:E$121,A5) -> 18 | G5: =IFERROR(VLOOKUP(A5,$I$4:$J$13,2,0),"N/A") -> Medium | I5: Software Licenses | J5: Medium
A6: Travel & Transport | B6: =IFERROR(SUMIF(Cleaned_Data!E$2:E$121,A6,Cleaned_Data!G$2:G$121),0) -> 15763839 | C6: =IFERROR(B6/SUM($B$4:$B$13),0) -> 0.055564602 | D6: =IFERROR(SUMIFS(Cleaned_Data!G$2:G$121,Cleaned_Data!E$2:E$121,A6,Cleaned_Data!I$2:I$121,"Approved"),0) -> 0 | E6: =IFERROR(B6/COUNTIF(Cleaned_Data!E$2:E$121,A6),0) -> 2251977.1 | F6: =COUNTIF(Cleaned_Data!E$2:E$121,A6) -> 7 | G6: =IFERROR(VLOOKUP(A6,$I$4:$J$13,2,0),"N/A") -> Medium | I6: Travel & Transport | J6: Medium
A7: Office Supplies | B7: =IFERROR(SUMIF(Cleaned_Data!E$2:E$121,A7,Cleaned_Data!G$2:G$121),0) -> 17649013 | C7: =IFERROR(B7/SUM($B$4:$B$13),0) -> 0.062209488 | D7: =IFERROR(SUMIFS(Cleaned_Data!G$2:G$121,Cleaned_Data!E$2:E$121,A7,Cleaned_Data!I$2:I$121,"Approved"),0) -> 0 | E7: =IFERROR(B7/COUNTIF(Cleaned_Data!E$2:E$121,A7),0) -> 1764901.3 | F7: =COUNTIF(Cleaned_Data!E$2:E$121,A7) -> 10 | G7: =IFERROR(VLOOKUP(A7,$I$4:$J$13,2,0),"N/A") -> Low | I7: Office Supplies | J7: Low
A8: Training | B8: =IFERROR(SUMIF(Cleaned_Data!E$2:E$121,A8,Cleaned_Data!G$2:G$121),0) -> 48612970 | C8: =IFERROR(B8/SUM($B$4:$B$13),0) -> 0.17135168 | D8: =IFERROR(SUMIFS(Cleaned_Data!G$2:G$121,Cleaned_Data!E$2:E$121,A8,Cleaned_Data!I$2:I$121,"Approved"),0) -> 0 | E8: =IFERROR(B8/COUNTIF(Cleaned_Data!E$2:E$121,A8),0) -> 2859586.5 | F8: =COUNTIF(Cleaned_Data!E$2:E$121,A8) -> 17 | G8: =IFERROR(VLOOKUP(A8,$I$4:$J$13,2,0),"N/A") -> Medium | I8: Training | J8: Medium
A9: Marketing | B9: =IFERROR(SUMIF(Cleaned_Data!E$2:E$121,A9,Cleaned_Data!G$2:G$121),0) -> 18742962 | C9: =IFERROR(B9/SUM($B$4:$B$13),0) -> 0.066065456 | D9: =IFERROR(SUMIFS(Cleaned_Data!G$2:G$121,Cleaned_Data!E$2:E$121,A9,Cleaned_Data!I$2:I$121,"Approved"),0) -> 0 | E9: =IFERROR(B9/COUNTIF(Cleaned_Data!E$2:E$121,A9),0) -> 2342870.3 | F9: =COUNTIF(Cleaned_Data!E$2:E$121,A9) -> 8 | G9: =IFERROR(VLOOKUP(A9,$I$4:$J$13,2,0),"N/A") -> Medium | I9: Marketing | J9: Medium
A10: Utilities | B10: =IFERROR(SUMIF(Cleaned_Data!E$2:E$121,A10,Cleaned_Data!G$2:G$121),0) -> 29475205 | C10: =IFERROR(B10/SUM($B$4:$B$13),0) -> 0.10389461 | D10: =IFERROR(SUMIFS(Cleaned_Data!G$2:G$121,Cleaned_Data!E$2:E$121,A10,Cleaned_Data!I$2:I$121,"Approved"),0) -> 0 | E10: =IFERROR(B10/COUNTIF(Cleaned_Data!E$2:E$121,A10),0) -> 2679564.1 | F10: =COUNTIF(Cleaned_Data!E$2:E$121,A10) -> 11 | G10: =IFERROR(VLOOKUP(A10,$I$4:$J$13,2,0),"N/A") -> High | I10: Utilities | J10: High
A11: Consulting Fees | B11: =IFERROR(SUMIF(Cleaned_Data!E$2:E$121,A11,Cleaned_Data!G$2:G$121),0) -> 29398524 | C11: =IFERROR(B11/SUM($B$4:$B$13),0) -> 0.10362433 | D11: =IFERROR(SUMIFS(Cleaned_Data!G$2:G$121,Cleaned_Data!E$2:E$121,A11,Cleaned_Data!I$2:I$121,"Approved"),0) -> 0 | E11: =IFERROR(B11/COUNTIF(Cleaned_Data!E$2:E$121,A11),0) -> 1959901.6 | F11: =COUNTIF(Cleaned_Data!E$2:E$121,A11) -> 15 | G11: =IFERROR(VLOOKUP(A11,$I$4:$J$13,2,0),"N/A") -> High | I11: Consulting Fees | J11: High
A12: Equipment | B12: =IFERROR(SUMIF(Cleaned_Data!E$2:E$121,A12,Cleaned_Data!G$2:G$121),0) -> 45536560 | C12: =IFERROR(B12/SUM($B$4:$B$13),0) -> 0.1605079 | D12: =IFERROR(SUMIFS(Cleaned_Data!G$2:G$121,Cleaned_Data!E$2:E$121,A12,Cleaned_Data!I$2:I$121,"Approved"),0) -> 0 | E12: =IFERROR(B12/COUNTIF(Cleaned_Data!E$2:E$121,A12),0) -> 2529808.9 | F12: =COUNTIF(Cleaned_Data!E$2:E$121,A12) -> 18 | G12: =IFERROR(VLOOKUP(A12,$I$4:$J$13,2,0),"N/A") -> Medium | I12: Equipment | J12: Medium
A13: Miscellaneous | B13: =IFERROR(SUMIF(Cleaned_Data!E$2:E$121,A13,Cleaned_Data!G$2:G$121),0) -> 23610360 | C13: =IFERROR(B13/SUM($B$4:$B$13),0) -> 0.083222126 | D13: =IFERROR(SUMIFS(Cleaned_Data!G$2:G$121,Cleaned_Data!E$2:E$121,A13,Cleaned_Data!I$2:I$121,"Approved"),0) -> 0 | E13: =IFERROR(B13/COUNTIF(Cleaned_Data!E$2:E$121,A13),0) -> 2361036 | F13: =COUNTIF(Cleaned_Data!E$2:E$121,A13) -> 10 | G13: =IFERROR(VLOOKUP(A13,$I$4:$J$13,2,0),"N/A") -> Low | I13: Miscellaneous | J13: Low
A14: TOTAL | B14: =SUM(B4:B13) -> 2.8370291e+08 | C14: =SUM(C4:C13) -> 1 | D14: =SUM(D4:D13) -> 0 | E14: =AVERAGE(E4:E13) -> 2312738.9 | F14: =SUM(F4:F13) -> 120
